## h1

予想 : 3秒経過後にAが出力され、そのあと2秒後にBが出力され、そのあと2秒後にCが出力される。
回答 : 同上
説明 : 各ステップでawaitで待機してから後続のコードが実行される。

## h2

予想 : Xが出力される。
回答 : 同上
説明 : new Promiseで即座にerrX()が実行され、スローされたエラーをPromise.catchで処理される。

// この辺からは、実行環境で変わるらしい。

## h3

予想 : Xが出力される。
回答 : エラーがでてプログラムが落ちる。
説明 : errXによってasync関数のPromiseがrejectされるが、new Promiseには影響しないためcatchで処理がされない。そのため、エラーでプログラムが落ちる。

## h4

予想 : 2秒経過後、Xが出力される。
回答 : `throw new Error("Y");`でエラーが生じてプログラムが落ちる。
説明 : p2のerrYが実行され、エラーがスローされたとき、`await p1`でp1の完了を待っているため、未処理のPromise rejectと検出されプログラムが落ちる。
